
// Case #1: try ... catch

try {
  console.log('success');
} catch (e) {
  console.log(e.message);
  console.log(e.notErrorMember);
}


// Case #2: not a try catch

function getObject<T>(): T {
  const object = ['dummy'];
  return object as unknown as T;
}

const dummy = getObject();

dummy.key;
